<?xml version="1.0" ?>
<robot name="zetabank" xmlns:xacro="http://ros.org/wiki/xacro">
  <xacro:include filename="$(find zetabank_description)/urdf/common_properties.xacro"/>

  
  <link name="base_footprint"/>

  <joint name="base_joint" type="fixed">
    <parent link="base_footprint"/>
    <child link="base_link" />
    <origin xyz="0 0 0.010" rpy="0 0 0"/>
  </joint>

  <link name="base_link">
    <visual>
      <origin xyz="-0 -0.33 0.0" rpy="0 0 ${M_PI*0.5}"/>
      <geometry>
        <mesh filename="package://zetabank_description/meshes/zetabank.STL" scale="1 1 1"/>
      </geometry>
      <material name="light_black"/>
    </visual>
    <collision>
      <origin xyz="0 0.064  0.048" rpy="0 0 0"/>
      <geometry>
        <box size="0.265 0.265 0.089"/>
      </geometry>
    </collision>
    <inertial>
      <origin xyz="0 0.064 0" rpy="0 0 0"/>
      <mass value="0.01"/>
      <inertia ixx="8.7002718e-03" ixy="-4.7576583e-05" ixz="1.1160499e-04" 
               iyy="8.6195418e-03" iyz="-3.5422299e-06" 
               izz="1.4612727e-02" /> 
    </inertial>

  </link>

<joint name="wheel_left_joint" type="continuous">
    <parent link="base_link"/>
    <child link="wheel_left_link"/>
    <origin xyz="0.0 0.180  0.075" rpy="${-M_PI*0.5} 0 0"/>
    <axis xyz="0 0 1"/>
  </joint>

  <link name="wheel_left_link">    
    <collision>
      <origin rpy="0 0 0" xyz="0 0 0"/>
      <geometry>
        <cylinder length="0.050" radius="0.0812"/>
      </geometry>
    </collision>
    <inertial>
      <origin xyz="0 0 0" />
      <mass value="2.8498940e-02" />
      <inertia ixx="1.1175580e-05" ixy="-4.2369783e-11" ixz="-5.9381719e-09"
               iyy="1.1192413e-05" iyz="-1.4400107e-11"
               izz="2.0712558e-05" />
      </inertial>
  </link>

  <joint name="wheel_right_joint" type="continuous">
    <parent link="base_link"/>
    <child link="wheel_right_link"/>
    <origin xyz="0.0 -0.180  0.075" rpy="${-M_PI*0.5} 0 0"/>
    <axis xyz="0 0 1"/>
  </joint>

  <link name="wheel_right_link">   
    <collision>
      <origin rpy="0 0 0" xyz="0 0 0"/>
      <geometry>
        <cylinder length="0.050" radius="0.0812"/>
      </geometry>
    </collision>
    <inertial>
      <origin xyz="0 0 0" />
      <mass value="2.8498940e-02" />
      <inertia ixx="1.1175580e-05" ixy="-4.2369783e-11" ixz="-5.9381719e-09"
               iyy="1.1192413e-05" iyz="-1.4400107e-11"
               izz="2.0712558e-05" />
      </inertial>
  </link>



  <joint name="imu_joint" type="fixed">
    <parent link="base_link"/>
    <child link="imu_link"/>
    <origin xyz="0.0 0.0 0.0" rpy="0 0 0"/>
  </joint>

  <link name="imu_link"/>


  <joint name="lidar_joint" type="fixed">
    <parent link="base_link"/>
    <child link="lidar_link"/>
    <origin xyz="0.1725 0.0 0.15" rpy="0 0 0"/>
  </joint>
  <link name="lidar_link"/>


    <joint name="lidar_joint_1" type="fixed">
    <parent link="base_link"/>
    <child link="lidar_link_1"/>
    <origin xyz="0.1725 0.0 0.15" rpy="0 0 0"/>
  </joint>
  <link name="lidar_link_1"/>
    <joint name="lidar_joint_2" type="fixed">
    <parent link="base_link"/>
    <child link="lidar_link_2"/>
    <origin xyz="0.1725 0.0 0.15" rpy="0 0 0"/>
  </joint>
  <link name="lidar_link_2"/>
    <joint name="camera_joint_1" type="fixed">
    <parent link="base_link"/>
    <child link="camera_1_depth"/>
    <origin xyz="0.21 0.1725 0.15" rpy="0 0 ${M_PI*0.25}"/>
  </joint>
  <link name="camera_1_depth"/>
    <joint name="camera_joint_2" type="fixed">
    <parent link="base_link"/>
    <child link="camera_2_depth"/>
    <origin xyz="0.21 -0.1725 0.15" rpy="0 0 ${-M_PI*0.25}"/>
  </joint>
  <link name="camera_2_depth"/>



</robot>